Workbook

Sheet График
A1: Тест
B2: !!! Версия !!! | C2: 1 | D2: График дежурств отъезд 16 октября 2025г
B4: Кол-во | C4: Кол-во | D4: Кол-во
B5: Общее кол-во приемов пищи | C5: Дежурств на 1 участника | D5: участников на данный день | F5: четверг | G5: пятница | H5: суббота | I5: воскресенье
B6: =COUNT(D8:D111) -> 11 | C6: =B6/D6 -> 2.2 | D6: 5 | F6: 16 | G6: 17 | H6: 18 | I6: 19
A8: 5 | B8: =F5 -> четверг | C8: Завтрак | D8: 5 | E8: Гречка | F8: Панин А
B9: =F6 -> 16 | C9: Обед | D9: 5 | E9: Без супа | F9: Панин С
C10: Ужин | D10: 5 | E10: Геркулес | F10: Рагулин С
B11: =G5 -> пятница | C11: Завтрак | D11: 5 | E11: Рис | G11: Ковалев Б
B12: =G6 -> 17 | C12: Обед | D12: 5 | E12: Без супа | G12: Волкова А
C13: Ужин | D13: 5 | E13: Макароны(сыр) | G13: Панин С
B14: =H5 -> суббота | C14: Завтрак | D14: 5 | E14: Гречка | H14: Панин А
B15: =H6 -> 18 | C15: Обед | D15: 5 | E15: Без супа | H15: Рагулин С
C16: Ужин | D16: 5 | E16: Пшенка | H16: Ковалев Б
B17: =I5 -> воскресенье | C17: Завтрак | D17: 5 | E17: Макароны(мясо) | I17: Волкова А
B18: =I6 -> 19 | C18: Обед | D18: 5 | E18: Без супа | I18: Панин С
C19: Ужин
B20: =J5 -> 0 | C20: Завтрак
B21: =J6 -> 0 | C21: Обед
C22: Ужин
B23: =K5 -> 0 | C23: Завтрак
B24: =K6 -> 0 | C24: Обед
C25: Ужин
B26: =L5 -> 0 | C26: Завтрак
B27: =L6 -> 0 | C27: Обед
C28: Ужин
A29: 4 | B29: =M5 -> 0 | C29: Завтрак
B30: =M6 -> 0 | C30: Обед
C31: Ужин
B32: =N5 -> 0 | C32: Завтрак
B33: =N6 -> 0 | C33: Обед
C34: Ужин
B35: =O5 -> 0 | C35: Завтрак
B36: =O6 -> 0 | C36: Обед
C37: Ужин
B38: =P5 -> 0 | C38: Завтрак
B39: =P6 -> 0 | C39: Обед
C40: Ужин
B41: =Q5 -> 0 | C41: Завтрак
B42: =Q6 -> 0 | C42: Обед
...

Sheet Шаблон
B1: 6 | C1: 8 | D1: 8 | E1: 8 | F1: 10 | G1: 8 | H1: 5 | I1: 8 | J1: 5 | K1: 8 | L1: 5 | M1: 8 | N1: 8 | O1: 6 | P1: 6 | Q1: 14 | R1: 8 | S1: 6 | T1: 9
D2: Калькулятор для раскладки | Q2: !!! Версия !!! | R2: =График!C2 -> 1
B5: Рассчет питания согласно графику дежурств | J5: 1 | K5: Коэффициент Стульникова | O5: отъезд 16 октября 2025г
G7: Геркулес | I7: Пшенка | K7: Мкароны(сыр)
B8: 1 | C8: Каша с молоком или макароны | E8: =SUM(G8,I8,K8) -> 0 | F8: = | G8: 0 | H8: + | I8: 0 | J8: + | K8: 0
B11: 2 | C11: Перекус. | F11: каждый выбирает на себя сам
G13: Харчо | I13: Борщ | K13: Гороховый | M13: Без супа
B14: 3 | C14: Обед. | E14: =SUM(G14,I14,K14,M14) -> 0 | F14: = | G14: 0 | H14: + | I14: 0 | J14: + | K14: 0 | L14: + | M14: 0
B17: 4 | C17: Перекус. | F17: каждый выбирает на себя сам
G19: Гречка | I19: Рис | K19: Макароны(мясо) | M19: Перловка
B20: 5 | C20: Каша с мясом | E20: =SUM(G20,I20,K20) -> 0 | F20: = | G20: 0 | H20: + | I20: 0 | J20: + | K20: 0 | L20: + | M20: =G20+I20 -> 0
C22: Общее | E22: =SUM(E8,E14,E20) -> 0 | I22: Кол-во | K22: Коэфф
I23: порций | K23: Стульникова
Q24: Общий вес гр. | T24: Цена
B26: 1 | C26: Завтрак
C27: 1 | D27: Гречка | G27: 90 | H27: × | I27: =G20 -> 0 | J27: × | K27: =J5 -> 1 | L27: = | M27: =PRODUCT(G27,I27,K27) -> 0 | Q27: =M27 -> 0
C28: 2 | D28: Рис | G28: 90 | H28: × | I28: =I20 -> 0 | J28: × | K28: =J5 -> 1 | L28: = | M28: =PRODUCT(G28,I28,K28) -> 0 | Q28: =M28 -> 0
C29: 3 | D29: Перловка | G29: 0 | H29: × | I29: =M20 -> 0 | J29: × | K29: =J5 -> 1 | L29: = | M29: =PRODUCT(G29,I29,K29) -> 0 | Q29: =M29 -> 0
C30: 4 | D30: Макароны(мясо) | G30: 90 | H30: × | I30: =K20 -> 0 | J30: × | K30: =J5 -> 1 | L30: = | M30: =PRODUCT(G30,I30,K30) -> 0 | Q30: =M30 -> 0
C31: 5 | D31: Тушенка | G31: 100 | H31: × | I31: =E20 -> 0 | J31: × | K31: =J5 -> 1 | L31: = | M31: =PRODUCT(G31,I31,K31) -> 0 | N31: 338 | Q31: =PRODUCT(M31)/N31 -> 0 | R31: банки | S31: =ROUNDUP(Q31, 0) -> 0
C32: 6 | D32: Печенье, 2 шт. | G32: 2 | H32: × | I32: =E20 -> 0 | J32: × | K32: =J5 -> 1 | L32: = | M32: =PRODUCT(G32,I32,K32) -> 0
C33: 7 | D33: Лимон в чай
B35: 2 | C35: Перекус.
B37: 3 | C37: Обед. | F37: супы на усмотрение участников
C38: 1 | D38: Бутерброд с копчен. | G38: 100 | H38: × | I38: =E14 -> 0 | J38: × | K38: =J5 -> 1 | L38: = | M38: =PRODUCT(G38,I38,K38) -> 0 | Q38: =M38 -> 0
C39: 2 | D39: Суп харчо | G39: 0.5 | H39: × | I39: =G14 -> 0 | J39: × | K39: =J5 -> 1 | L39: = | M39: =PRODUCT(G39,I39,K39) -> 0
C40: 3 | D40: Борщ | G40: 0.5 | H40: × | I40: =I14 -> 0 | J40: × | K40: =J5 -> 1 | L40: = | M40: =PRODUCT(G40,I40,K40) -> 0
C41: 4 | D41: Гороховый | G41: 0.5 | H41: × | I41: =K14 -> 0 | J41: × | K41: =J5 -> 1 | L41: = | M41: =PRODUCT(G41,I41,K41) -> 0
C42: 5 | D42: Сухари | G42: 2 | H42: × | I42: =E14 -> 0 | J42: × | K42: =J5 -> 1 | L42: = | M42: =PRODUCT(G42,I42,K42) -> 0 | Q42: =PRODUCT(20,M42) -> 0
C43: 6 | D43: Репчатый лук | G43: 0.25 | H43: × | I43: =E14 -> 0 | J43: × | K43: =J5 -> 1 | L43: = | M43: =PRODUCT(G43,I43,K43) -> 0 | Q43: =M43 -> 0 | R43: средних
C44: 7 | D44: Лимон в чай
C45: 8 | D45: Взять термос (небольшой)
B46: 4 | C46: Перекус.
B48: 5 | C48: Ужин
C49: 1 | D49: Геркулес | G49: 90 | H49: × | I49: =G8 -> 0 | J49: × | K49: =J5 -> 1 | L49: = | M49: =PRODUCT(G49,I49,K49) -> 0 | Q49: =M49 -> 0
C50: 2 | D50: Пшенка | G50: 80 | H50: × | I50: =I8 -> 0 | J50: × | K50: =J5 -> 1 | L50: = | M50: =PRODUCT(G50,I50,K50) -> 0 | Q50: =M50 -> 0
C51: 3 | D51: Сгущеное молоко | G51: 25 | H51: × | I51: =E8 -> 0 | J51: × | K51: =J5 -> 1 | L51: = | M51: =PRODUCT(G51,I51,K51) -> 0 | Q51: =M51 -> 0
C52: 4 | D52: Макароны(сыр) | G52: 80 | H52: × | I52: =K8 -> 0 | J52: × | K52: =J5 -> 1 | L52: = | M52: =PRODUCT(G52,I52,K52) -> 0 | Q52: =M52 -> 0
C53: 5 | D53: Топленое(сливочное) масло | G53: 25 | H53: × | I53: =E8 -> 0 | J53: × | K53: =J5 -> 1 | L53: = | M53: =PRODUCT(G53,I53,K53) -> 0 | Q53: =M53 -> 0
C54: 6 | D54: Изюм по 1 ст. ложке | G54: 25 | H54: × | I54: =E8 -> 0 | J54: × | K54: =J5 -> 1 | L54: = | M54: =PRODUCT(G54,I54,K54) -> 0 | Q54: =M54 -> 0
...

Sheet Волкова А
B1: 6 | C1: 8 | D1: 8 | E1: 8 | F1: 10 | G1: 8 | H1: 5 | I1: 8 | J1: 5 | K1: 8 | L1: 5 | M1: 8 | N1: 8 | O1: 6 | P1: 6 | Q1: 14 | R1: 8 | S1: 6 | T1: 9
D2: Калькулятор для раскладки | I2: Волкова А | Q2: !!! Версия !!! | R2: =График!C2 -> 1
B5: Рассчет питания согласно графику дежурств | J5: 1 | K5: Коэффициент Стульникова | O5: отъезд 16 октября 2025г
G7: Геркулес | I7: Пшенка | K7: Мкароны(сыр)
B8: 1 | C8: Каша с молоком или макароны | E8: =SUM(G8,I8,K8) -> 0 | F8: = | G8: 0 | H8: + | I8: 0 | J8: + | K8: 0
B11: 2 | C11: Перекус. | F11: каждый выбирает на себя сам
G13: Харчо | I13: Борщ | K13: Гороховый | M13: Без супа
B14: 3 | C14: Обед. | E14: =SUM(G14,I14,K14,M14) -> 5 | F14: = | G14: 0 | H14: + | I14: 0 | J14: + | K14: 0 | L14: + | M14: 5
B17: 4 | C17: Перекус. | F17: каждый выбирает на себя сам
G19: Гречка | I19: Рис | K19: Макароны(мясо) | M19: Перловка
B20: 5 | C20: Каша с мясом | E20: =SUM(G20,I20,K20) -> 5 | F20: = | G20: 0 | H20: + | I20: 0 | J20: + | K20: 5 | L20: + | M20: =G20+I20 -> 0
C22: Общее | E22: =SUM(E8,E14,E20) -> 10 | I22: Кол-во | K22: Коэфф
I23: порций | K23: Стульникова
Q24: Общий вес гр. | T24: Цена
B26: 1 | C26: Завтрак
C27: 1 | D27: Гречка | G27: 90 | H27: × | I27: =G20 -> 0 | J27: × | K27: =J5 -> 1 | L27: = | M27: =PRODUCT(G27,I27,K27) -> 0 | Q27: =M27 -> 0
C28: 2 | D28: Рис | G28: 90 | H28: × | I28: =I20 -> 0 | J28: × | K28: =J5 -> 1 | L28: = | M28: =PRODUCT(G28,I28,K28) -> 0 | Q28: =M28 -> 0
C29: 3 | D29: Перловка | G29: 0 | H29: × | I29: =M20 -> 0 | J29: × | K29: =J5 -> 1 | L29: = | M29: =PRODUCT(G29,I29,K29) -> 0 | Q29: =M29 -> 0
C30: 4 | D30: Макароны(мясо) | G30: 90 | H30: × | I30: =K20 -> 5 | J30: × | K30: =J5 -> 1 | L30: = | M30: =PRODUCT(G30,I30,K30) -> 450 | Q30: =M30 -> 450
C31: 5 | D31: Тушенка | G31: 100 | H31: × | I31: =E20 -> 5 | J31: × | K31: =J5 -> 1 | L31: = | M31: =PRODUCT(G31,I31,K31) -> 500 | N31: 338 | Q31: =PRODUCT(M31)/N31 -> 1.4792899 | R31: банки | S31: =ROUNDUP(Q31, 0) -> 2
C32: 6 | D32: Печенье, 2 шт. | G32: 2 | H32: × | I32: =E20 -> 5 | J32: × | K32: =J5 -> 1 | L32: = | M32: =PRODUCT(G32,I32,K32) -> 10
C33: 7 | D33: Лимон в чай
B35: 2 | C35: Перекус.
B37: 3 | C37: Обед. | F37: супы на усмотрение участников
C38: 1 | D38: Бутерброд с копчен. | G38: 100 | H38: × | I38: =E14 -> 5 | J38: × | K38: =J5 -> 1 | L38: = | M38: =PRODUCT(G38,I38,K38) -> 500 | Q38: =M38 -> 500
C39: 2 | D39: Суп харчо | G39: 0.5 | H39: × | I39: =G14 -> 0 | J39: × | K39: =J5 -> 1 | L39: = | M39: =PRODUCT(G39,I39,K39) -> 0
C40: 3 | D40: Борщ | G40: 0.5 | H40: × | I40: =I14 -> 0 | J40: × | K40: =J5 -> 1 | L40: = | M40: =PRODUCT(G40,I40,K40) -> 0
C41: 4 | D41: Гороховый | G41: 0.5 | H41: × | I41: =K14 -> 0 | J41: × | K41: =J5 -> 1 | L41: = | M41: =PRODUCT(G41,I41,K41) -> 0
C42: 5 | D42: Сухари | G42: 2 | H42: × | I42: =E14 -> 5 | J42: × | K42: =J5 -> 1 | L42: = | M42: =PRODUCT(G42,I42,K42) -> 10 | Q42: =PRODUCT(20,M42) -> 200
C43: 6 | D43: Репчатый лук | G43: 0.25 | H43: × | I43: =E14 -> 5 | J43: × | K43: =J5 -> 1 | L43: = | M43: =PRODUCT(G43,I43,K43) -> 1.25 | Q43: =M43 -> 1.25 | R43: средних
C44: 7 | D44: Лимон в чай
C45: 8 | D45: Взять термос (небольшой)
B46: 4 | C46: Перекус.
B48: 5 | C48: Ужин
C49: 1 | D49: Геркулес | G49: 90 | H49: × | I49: =G8 -> 0 | J49: × | K49: =J5 -> 1 | L49: = | M49: =PRODUCT(G49,I49,K49) -> 0 | Q49: =M49 -> 0
C50: 2 | D50: Пшенка | G50: 80 | H50: × | I50: =I8 -> 0 | J50: × | K50: =J5 -> 1 | L50: = | M50: =PRODUCT(G50,I50,K50) -> 0 | Q50: =M50 -> 0
C51: 3 | D51: Сгущеное молоко | G51: 25 | H51: × | I51: =E8 -> 0 | J51: × | K51: =J5 -> 1 | L51: = | M51: =PRODUCT(G51,I51,K51) -> 0 | Q51: =M51 -> 0
C52: 4 | D52: Макароны(сыр) | G52: 80 | H52: × | I52: =K8 -> 0 | J52: × | K52: =J5 -> 1 | L52: = | M52: =PRODUCT(G52,I52,K52) -> 0 | Q52: =M52 -> 0
C53: 5 | D53: Топленое(сливочное) масло | G53: 25 | H53: × | I53: =E8 -> 0 | J53: × | K53: =J5 -> 1 | L53: = | M53: =PRODUCT(G53,I53,K53) -> 0 | Q53: =M53 -> 0
C54: 6 | D54: Изюм по 1 ст. ложке | G54: 25 | H54: × | I54: =E8 -> 0 | J54: × | K54: =J5 -> 1 | L54: = | M54: =PRODUCT(G54,I54,K54) -> 0 | Q54: =M54 -> 0
...

Sheet Ковалев Б
B1: 6 | C1: 8 | D1: 8 | E1: 8 | F1: 10 | G1: 8 | H1: 5 | I1: 8 | J1: 5 | K1: 8 | L1: 5 | M1: 8 | N1: 8 | O1: 6 | P1: 6 | Q1: 14 | R1: 8 | S1: 6 | T1: 9
D2: Калькулятор для раскладки | I2: Ковалев Б | Q2: !!! Версия !!! | R2: =График!C2 -> 1
B5: Рассчет питания согласно графику дежурств | J5: 1 | K5: Коэффициент Стульникова | O5: отъезд 16 октября 2025г
G7: Геркулес | I7: Пшенка | K7: Мкароны(сыр)
B8: 1 | C8: Каша с молоком или макароны | E8: =SUM(G8,I8,K8) -> 5 | F8: = | G8: 0 | H8: + | I8: 5 | J8: + | K8: 0
B11: 2 | C11: Перекус. | F11: каждый выбирает на себя сам
G13: Харчо | I13: Борщ | K13: Гороховый | M13: Без супа
B14: 3 | C14: Обед. | E14: =SUM(G14,I14,K14,M14) -> 0 | F14: = | G14: 0 | H14: + | I14: 0 | J14: + | K14: 0 | L14: + | M14: 0
B17: 4 | C17: Перекус. | F17: каждый выбирает на себя сам
G19: Гречка | I19: Рис | K19: Макароны(мясо) | M19: Перловка
B20: 5 | C20: Каша с мясом | E20: =SUM(G20,I20,K20) -> 5 | F20: = | G20: 0 | H20: + | I20: 5 | J20: + | K20: 0 | L20: + | M20: =G20+I20 -> 5
C22: Общее | E22: =SUM(E8,E14,E20) -> 10 | I22: Кол-во | K22: Коэфф
I23: порций | K23: Стульникова
Q24: Общий вес гр. | T24: Цена
B26: 1 | C26: Завтрак
C27: 1 | D27: Гречка | G27: 90 | H27: × | I27: =G20 -> 0 | J27: × | K27: =J5 -> 1 | L27: = | M27: =PRODUCT(G27,I27,K27) -> 0 | Q27: =M27 -> 0
C28: 2 | D28: Рис | G28: 90 | H28: × | I28: =I20 -> 5 | J28: × | K28: =J5 -> 1 | L28: = | M28: =PRODUCT(G28,I28,K28) -> 450 | Q28: =M28 -> 450
C29: 3 | D29: Перловка | G29: 0 | H29: × | I29: =M20 -> 5 | J29: × | K29: =J5 -> 1 | L29: = | M29: =PRODUCT(G29,I29,K29) -> 0 | Q29: =M29 -> 0
C30: 4 | D30: Макароны(мясо) | G30: 90 | H30: × | I30: =K20 -> 0 | J30: × | K30: =J5 -> 1 | L30: = | M30: =PRODUCT(G30,I30,K30) -> 0 | Q30: =M30 -> 0
C31: 5 | D31: Тушенка | G31: 100 | H31: × | I31: =E20 -> 5 | J31: × | K31: =J5 -> 1 | L31: = | M31: =PRODUCT(G31,I31,K31) -> 500 | N31: 338 | Q31: =PRODUCT(M31)/N31 -> 1.4792899 | R31: банки | S31: =ROUNDUP(Q31, 0) -> 2
C32: 6 | D32: Печенье, 2 шт. | G32: 2 | H32: × | I32: =E20 -> 5 | J32: × | K32: =J5 -> 1 | L32: = | M32: =PRODUCT(G32,I32,K32) -> 10
C33: 7 | D33: Лимон в чай
B35: 2 | C35: Перекус.
B37: 3 | C37: Обед. | F37: супы на усмотрение участников
C38: 1 | D38: Бутерброд с копчен. | G38: 100 | H38: × | I38: =E14 -> 0 | J38: × | K38: =J5 -> 1 | L38: = | M38: =PRODUCT(G38,I38,K38) -> 0 | Q38: =M38 -> 0
C39: 2 | D39: Суп харчо | G39: 0.5 | H39: × | I39: =G14 -> 0 | J39: × | K39: =J5 -> 1 | L39: = | M39: =PRODUCT(G39,I39,K39) -> 0
C40: 3 | D40: Борщ | G40: 0.5 | H40: × | I40: =I14 -> 0 | J40: × | K40: =J5 -> 1 | L40: = | M40: =PRODUCT(G40,I40,K40) -> 0
C41: 4 | D41: Гороховый | G41: 0.5 | H41: × | I41: =K14 -> 0 | J41: × | K41: =J5 -> 1 | L41: = | M41: =PRODUCT(G41,I41,K41) -> 0
C42: 5 | D42: Сухари | G42: 2 | H42: × | I42: =E14 -> 0 | J42: × | K42: =J5 -> 1 | L42: = | M42: =PRODUCT(G42,I42,K42) -> 0 | Q42: =PRODUCT(20,M42) -> 0
C43: 6 | D43: Репчатый лук | G43: 0.25 | H43: × | I43: =E14 -> 0 | J43: × | K43: =J5 -> 1 | L43: = | M43: =PRODUCT(G43,I43,K43) -> 0 | Q43: =M43 -> 0 | R43: средних
C44: 7 | D44: Лимон в чай
C45: 8 | D45: Взять термос (небольшой)
B46: 4 | C46: Перекус.
B48: 5 | C48: Ужин
C49: 1 | D49: Геркулес | G49: 90 | H49: × | I49: =G8 -> 0 | J49: × | K49: =J5 -> 1 | L49: = | M49: =PRODUCT(G49,I49,K49) -> 0 | Q49: =M49 -> 0
C50: 2 | D50: Пшенка | G50: 80 | H50: × | I50: =I8 -> 5 | J50: × | K50: =J5 -> 1 | L50: = | M50: =PRODUCT(G50,I50,K50) -> 400 | Q50: =M50 -> 400
C51: 3 | D51: Сгущеное молоко | G51: 25 | H51: × | I51: =E8 -> 5 | J51: × | K51: =J5 -> 1 | L51: = | M51: =PRODUCT(G51,I51,K51) -> 125 | Q51: =M51 -> 125
C52: 4 | D52: Макароны(сыр) | G52: 80 | H52: × | I52: =K8 -> 0 | J52: × | K52: =J5 -> 1 | L52: = | M52: =PRODUCT(G52,I52,K52) -> 0 | Q52: =M52 -> 0
C53: 5 | D53: Топленое(сливочное) масло | G53: 25 | H53: × | I53: =E8 -> 5 | J53: × | K53: =J5 -> 1 | L53: = | M53: =PRODUCT(G53,I53,K53) -> 125 | Q53: =M53 -> 125
C54: 6 | D54: Изюм по 1 ст. ложке | G54: 25 | H54: × | I54: =E8 -> 5 | J54: × | K54: =J5 -> 1 | L54: = | M54: =PRODUCT(G54,I54,K54) -> 125 | Q54: =M54 -> 125
...

Sheet Панин А
B1: 6 | C1: 8 | D1: 8 | E1: 8 | F1: 10 | G1: 8 | H1: 5 | I1: 8 | J1: 5 | K1: 8 | L1: 5 | M1: 8 | N1: 8 | O1: 6 | P1: 6 | Q1: 14 | R1: 8 | S1: 6 | T1: 9
D2: Калькулятор для раскладки | I2: Панин А | Q2: !!! Версия !!! | R2: =График!C2 -> 1
B5: Рассчет питания согласно графику дежурств | J5: 1 | K5: Коэффициент Стульникова | O5: отъезд 16 октября 2025г
G7: Геркулес | I7: Пшенка | K7: Мкароны(сыр)
B8: 1 | C8: Каша с молоком или макароны | E8: =SUM(G8,I8,K8) -> 0 | F8: = | G8: 0 | H8: + | I8: 0 | J8: + | K8: 0
B11: 2 | C11: Перекус. | F11: каждый выбирает на себя сам
G13: Харчо | I13: Борщ | K13: Гороховый | M13: Без супа
B14: 3 | C14: Обед. | E14: =SUM(G14,I14,K14,M14) -> 0 | F14: = | G14: 0 | H14: + | I14: 0 | J14: + | K14: 0 | L14: + | M14: 0
B17: 4 | C17: Перекус. | F17: каждый выбирает на себя сам
G19: Гречка | I19: Рис | K19: Макароны(мясо) | M19: Перловка
B20: 5 | C20: Каша с мясом | E20: =SUM(G20,I20,K20) -> 10 | F20: = | G20: 10 | H20: + | I20: 0 | J20: + | K20: 0 | L20: + | M20: =G20+I20 -> 10
C22: Общее | E22: =SUM(E8,E14,E20) -> 10 | I22: Кол-во | K22: Коэфф
I23: порций | K23: Стульникова
Q24: Общий вес гр. | T24: Цена
B26: 1 | C26: Завтрак
C27: 1 | D27: Гречка | G27: 90 | H27: × | I27: =G20 -> 10 | J27: × | K27: =J5 -> 1 | L27: = | M27: =PRODUCT(G27,I27,K27) -> 900 | Q27: =M27 -> 900
C28: 2 | D28: Рис | G28: 90 | H28: × | I28: =I20 -> 0 | J28: × | K28: =J5 -> 1 | L28: = | M28: =PRODUCT(G28,I28,K28) -> 0 | Q28: =M28 -> 0
C29: 3 | D29: Перловка | G29: 0 | H29: × | I29: =M20 -> 10 | J29: × | K29: =J5 -> 1 | L29: = | M29: =PRODUCT(G29,I29,K29) -> 0 | Q29: =M29 -> 0
C30: 4 | D30: Макароны(мясо) | G30: 90 | H30: × | I30: =K20 -> 0 | J30: × | K30: =J5 -> 1 | L30: = | M30: =PRODUCT(G30,I30,K30) -> 0 | Q30: =M30 -> 0
C31: 5 | D31: Тушенка | G31: 100 | H31: × | I31: =E20 -> 10 | J31: × | K31: =J5 -> 1 | L31: = | M31: =PRODUCT(G31,I31,K31) -> 1000 | N31: 338 | Q31: =PRODUCT(M31)/N31 -> 2.9585799 | R31: банки | S31: =ROUNDUP(Q31, 0) -> 3
C32: 6 | D32: Печенье, 2 шт. | G32: 2 | H32: × | I32: =E20 -> 10 | J32: × | K32: =J5 -> 1 | L32: = | M32: =PRODUCT(G32,I32,K32) -> 20
C33: 7 | D33: Лимон в чай
B35: 2 | C35: Перекус.
B37: 3 | C37: Обед. | F37: супы на усмотрение участников
C38: 1 | D38: Бутерброд с копчен. | G38: 100 | H38: × | I38: =E14 -> 0 | J38: × | K38: =J5 -> 1 | L38: = | M38: =PRODUCT(G38,I38,K38) -> 0 | Q38: =M38 -> 0
C39: 2 | D39: Суп харчо | G39: 0.5 | H39: × | I39: =G14 -> 0 | J39: × | K39: =J5 -> 1 | L39: = | M39: =PRODUCT(G39,I39,K39) -> 0
C40: 3 | D40: Борщ | G40: 0.5 | H40: × | I40: =I14 -> 0 | J40: × | K40: =J5 -> 1 | L40: = | M40: =PRODUCT(G40,I40,K40) -> 0
C41: 4 | D41: Гороховый | G41: 0.5 | H41: × | I41: =K14 -> 0 | J41: × | K41: =J5 -> 1 | L41: = | M41: =PRODUCT(G41,I41,K41) -> 0
C42: 5 | D42: Сухари | G42: 2 | H42: × | I42: =E14 -> 0 | J42: × | K42: =J5 -> 1 | L42: = | M42: =PRODUCT(G42,I42,K42) -> 0 | Q42: =PRODUCT(20,M42) -> 0
C43: 6 | D43: Репчатый лук | G43: 0.25 | H43: × | I43: =E14 -> 0 | J43: × | K43: =J5 -> 1 | L43: = | M43: =PRODUCT(G43,I43,K43) -> 0 | Q43: =M43 -> 0 | R43: средних
C44: 7 | D44: Лимон в чай
C45: 8 | D45: Взять термос (небольшой)
B46: 4 | C46: Перекус.
B48: 5 | C48: Ужин
C49: 1 | D49: Геркулес | G49: 90 | H49: × | I49: =G8 -> 0 | J49: × | K49: =J5 -> 1 | L49: = | M49: =PRODUCT(G49,I49,K49) -> 0 | Q49: =M49 -> 0
C50: 2 | D50: Пшенка | G50: 80 | H50: × | I50: =I8 -> 0 | J50: × | K50: =J5 -> 1 | L50: = | M50: =PRODUCT(G50,I50,K50) -> 0 | Q50: =M50 -> 0
C51: 3 | D51: Сгущеное молоко | G51: 25 | H51: × | I51: =E8 -> 0 | J51: × | K51: =J5 -> 1 | L51: = | M51: =PRODUCT(G51,I51,K51) -> 0 | Q51: =M51 -> 0
C52: 4 | D52: Макароны(сыр) | G52: 80 | H52: × | I52: =K8 -> 0 | J52: × | K52: =J5 -> 1 | L52: = | M52: =PRODUCT(G52,I52,K52) -> 0 | Q52: =M52 -> 0
C53: 5 | D53: Топленое(сливочное) масло | G53: 25 | H53: × | I53: =E8 -> 0 | J53: × | K53: =J5 -> 1 | L53: = | M53: =PRODUCT(G53,I53,K53) -> 0 | Q53: =M53 -> 0
C54: 6 | D54: Изюм по 1 ст. ложке | G54: 25 | H54: × | I54: =E8 -> 0 | J54: × | K54: =J5 -> 1 | L54: = | M54: =PRODUCT(G54,I54,K54) -> 0 | Q54: =M54 -> 0
...

Sheet Панин С
B1: 6 | C1: 8 | D1: 8 | E1: 8 | F1: 10 | G1: 8 | H1: 5 | I1: 8 | J1: 5 | K1: 8 | L1: 5 | M1: 8 | N1: 8 | O1: 6 | P1: 6 | Q1: 14 | R1: 8 | S1: 6 | T1: 9
D2: Калькулятор для раскладки | I2: Панин С | Q2: !!! Версия !!! | R2: =График!C2 -> 1
B5: Рассчет питания согласно графику дежурств | J5: 1 | K5: Коэффициент Стульникова | O5: отъезд 16 октября 2025г
G7: Геркулес | I7: Пшенка | K7: Мкароны(сыр)
B8: 1 | C8: Каша с молоком или макароны | E8: =SUM(G8,I8,K8) -> 5 | F8: = | G8: 0 | H8: + | I8: 0 | J8: + | K8: 5
B11: 2 | C11: Перекус. | F11: каждый выбирает на себя сам
G13: Харчо | I13: Борщ | K13: Гороховый | M13: Без супа
B14: 3 | C14: Обед. | E14: =SUM(G14,I14,K14,M14) -> 10 | F14: = | G14: 0 | H14: + | I14: 0 | J14: + | K14: 0 | L14: + | M14: 10
B17: 4 | C17: Перекус. | F17: каждый выбирает на себя сам
G19: Гречка | I19: Рис | K19: Макароны(мясо) | M19: Перловка
B20: 5 | C20: Каша с мясом | E20: =SUM(G20,I20,K20) -> 0 | F20: = | G20: 0 | H20: + | I20: 0 | J20: + | K20: 0 | L20: + | M20: =G20+I20 -> 0
C22: Общее | E22: =SUM(E8,E14,E20) -> 15 | I22: Кол-во | K22: Коэфф
I23: порций | K23: Стульникова
Q24: Общий вес гр. | T24: Цена
B26: 1 | C26: Завтрак
C27: 1 | D27: Гречка | G27: 90 | H27: × | I27: =G20 -> 0 | J27: × | K27: =J5 -> 1 | L27: = | M27: =PRODUCT(G27,I27,K27) -> 0 | Q27: =M27 -> 0
C28: 2 | D28: Рис | G28: 90 | H28: × | I28: =I20 -> 0 | J28: × | K28: =J5 -> 1 | L28: = | M28: =PRODUCT(G28,I28,K28) -> 0 | Q28: =M28 -> 0
C29: 3 | D29: Перловка | G29: 0 | H29: × | I29: =M20 -> 0 | J29: × | K29: =J5 -> 1 | L29: = | M29: =PRODUCT(G29,I29,K29) -> 0 | Q29: =M29 -> 0
C30: 4 | D30: Макароны(мясо) | G30: 90 | H30: × | I30: =K20 -> 0 | J30: × | K30: =J5 -> 1 | L30: = | M30: =PRODUCT(G30,I30,K30) -> 0 | Q30: =M30 -> 0
C31: 5 | D31: Тушенка | G31: 100 | H31: × | I31: =E20 -> 0 | J31: × | K31: =J5 -> 1 | L31: = | M31: =PRODUCT(G31,I31,K31) -> 0 | N31: 338 | Q31: =PRODUCT(M31)/N31 -> 0 | R31: банки | S31: =ROUNDUP(Q31, 0) -> 0
C32: 6 | D32: Печенье, 2 шт. | G32: 2 | H32: × | I32: =E20 -> 0 | J32: × | K32: =J5 -> 1 | L32: = | M32: =PRODUCT(G32,I32,K32) -> 0
C33: 7 | D33: Лимон в чай
B35: 2 | C35: Перекус.
B37: 3 | C37: Обед. | F37: супы на усмотрение участников
C38: 1 | D38: Бутерброд с копчен. | G38: 100 | H38: × | I38: =E14 -> 10 | J38: × | K38: =J5 -> 1 | L38: = | M38: =PRODUCT(G38,I38,K38) -> 1000 | Q38: =M38 -> 1000
C39: 2 | D39: Суп харчо | G39: 0.5 | H39: × | I39: =G14 -> 0 | J39: × | K39: =J5 -> 1 | L39: = | M39: =PRODUCT(G39,I39,K39) -> 0
C40: 3 | D40: Борщ | G40: 0.5 | H40: × | I40: =I14 -> 0 | J40: × | K40: =J5 -> 1 | L40: = | M40: =PRODUCT(G40,I40,K40) -> 0
C41: 4 | D41: Гороховый | G41: 0.5 | H41: × | I41: =K14 -> 0 | J41: × | K41: =J5 -> 1 | L41: = | M41: =PRODUCT(G41,I41,K41) -> 0
C42: 5 | D42: Сухари | G42: 2 | H42: × | I42: =E14 -> 10 | J42: × | K42: =J5 -> 1 | L42: = | M42: =PRODUCT(G42,I42,K42) -> 20 | Q42: =PRODUCT(20,M42) -> 400
C43: 6 | D43: Репчатый лук | G43: 0.25 | H43: × | I43: =E14 -> 10 | J43: × | K43: =J5 -> 1 | L43: = | M43: =PRODUCT(G43,I43,K43) -> 2.5 | Q43: =M43 -> 2.5 | R43: средних
C44: 7 | D44: Лимон в чай
C45: 8 | D45: Взять термос (небольшой)
B46: 4 | C46: Перекус.
B48: 5 | C48: Ужин
C49: 1 | D49: Геркулес | G49: 90 | H49: × | I49: =G8 -> 0 | J49: × | K49: =J5 -> 1 | L49: = | M49: =PRODUCT(G49,I49,K49) -> 0 | Q49: =M49 -> 0
C50: 2 | D50: Пшенка | G50: 80 | H50: × | I50: =I8 -> 0 | J50: × | K50: =J5 -> 1 | L50: = | M50: =PRODUCT(G50,I50,K50) -> 0 | Q50: =M50 -> 0
C51: 3 | D51: Сгущеное молоко | G51: 25 | H51: × | I51: =E8 -> 5 | J51: × | K51: =J5 -> 1 | L51: = | M51: =PRODUCT(G51,I51,K51) -> 125 | Q51: =M51 -> 125
C52: 4 | D52: Макароны(сыр) | G52: 80 | H52: × | I52: =K8 -> 5 | J52: × | K52: =J5 -> 1 | L52: = | M52: =PRODUCT(G52,I52,K52) -> 400 | Q52: =M52 -> 400
C53: 5 | D53: Топленое(сливочное) масло | G53: 25 | H53: × | I53: =E8 -> 5 | J53: × | K53: =J5 -> 1 | L53: = | M53: =PRODUCT(G53,I53,K53) -> 125 | Q53: =M53 -> 125
C54: 6 | D54: Изюм по 1 ст. ложке | G54: 25 | H54: × | I54: =E8 -> 5 | J54: × | K54: =J5 -> 1 | L54: = | M54: =PRODUCT(G54,I54,K54) -> 125 | Q54: =M54 -> 125
...

Sheet Рагулин С
B1: 6 | C1: 8 | D1: 8 | E1: 8 | F1: 10 | G1: 8 | H1: 5 | I1: 8 | J1: 5 | K1: 8 | L1: 5 | M1: 8 | N1: 8 | O1: 6 | P1: 6 | Q1: 14 | R1: 8 | S1: 6 | T1: 9
D2: Калькулятор для раскладки | I2: Рагулин С | Q2: !!! Версия !!! | R2: =График!C2 -> 1
B5: Рассчет питания согласно графику дежурств | J5: 1 | K5: Коэффициент Стульникова | O5: отъезд 16 октября 2025г
G7: Геркулес | I7: Пшенка | K7: Мкароны(сыр)
B8: 1 | C8: Каша с молоком или макароны | E8: =SUM(G8,I8,K8) -> 5 | F8: = | G8: 5 | H8: + | I8: 0 | J8: + | K8: 0
B11: 2 | C11: Перекус. | F11: каждый выбирает на себя сам
G13: Харчо | I13: Борщ | K13: Гороховый | M13: Без супа
B14: 3 | C14: Обед. | E14: =SUM(G14,I14,K14,M14) -> 5 | F14: = | G14: 0 | H14: + | I14: 0 | J14: + | K14: 0 | L14: + | M14: 5
B17: 4 | C17: Перекус. | F17: каждый выбирает на себя сам
G19: Гречка | I19: Рис | K19: Макароны(мясо) | M19: Перловка
B20: 5 | C20: Каша с мясом | E20: =SUM(G20,I20,K20) -> 0 | F20: = | G20: 0 | H20: + | I20: 0 | J20: + | K20: 0 | L20: + | M20: =G20+I20 -> 0
C22: Общее | E22: =SUM(E8,E14,E20) -> 10 | I22: Кол-во | K22: Коэфф
I23: порций | K23: Стульникова
Q24: Общий вес гр. | T24: Цена
B26: 1 | C26: Завтрак
C27: 1 | D27: Гречка | G27: 90 | H27: × | I27: =G20 -> 0 | J27: × | K27: =J5 -> 1 | L27: = | M27: =PRODUCT(G27,I27,K27) -> 0 | Q27: =M27 -> 0
C28: 2 | D28: Рис | G28: 90 | H28: × | I28: =I20 -> 0 | J28: × | K28: =J5 -> 1 | L28: = | M28: =PRODUCT(G28,I28,K28) -> 0 | Q28: =M28 -> 0
C29: 3 | D29: Перловка | G29: 0 | H29: × | I29: =M20 -> 0 | J29: × | K29: =J5 -> 1 | L29: = | M29: =PRODUCT(G29,I29,K29) -> 0 | Q29: =M29 -> 0
C30: 4 | D30: Макароны(мясо) | G30: 90 | H30: × | I30: =K20 -> 0 | J30: × | K30: =J5 -> 1 | L30: = | M30: =PRODUCT(G30,I30,K30) -> 0 | Q30: =M30 -> 0
C31: 5 | D31: Тушенка | G31: 100 | H31: × | I31: =E20 -> 0 | J31: × | K31: =J5 -> 1 | L31: = | M31: =PRODUCT(G31,I31,K31) -> 0 | N31: 338 | Q31: =PRODUCT(M31)/N31 -> 0 | R31: банки | S31: =ROUNDUP(Q31, 0) -> 0
C32: 6 | D32: Печенье, 2 шт. | G32: 2 | H32: × | I32: =E20 -> 0 | J32: × | K32: =J5 -> 1 | L32: = | M32: =PRODUCT(G32,I32,K32) -> 0
C33: 7 | D33: Лимон в чай
B35: 2 | C35: Перекус.
B37: 3 | C37: Обед. | F37: супы на усмотрение участников
C38: 1 | D38: Бутерброд с копчен. | G38: 100 | H38: × | I38: =E14 -> 5 | J38: × | K38: =J5 -> 1 | L38: = | M38: =PRODUCT(G38,I38,K38) -> 500 | Q38: =M38 -> 500
C39: 2 | D39: Суп харчо | G39: 0.5 | H39: × | I39: =G14 -> 0 | J39: × | K39: =J5 -> 1 | L39: = | M39: =PRODUCT(G39,I39,K39) -> 0
C40: 3 | D40: Борщ | G40: 0.5 | H40: × | I40: =I14 -> 0 | J40: × | K40: =J5 -> 1 | L40: = | M40: =PRODUCT(G40,I40,K40) -> 0
C41: 4 | D41: Гороховый | G41: 0.5 | H41: × | I41: =K14 -> 0 | J41: × | K41: =J5 -> 1 | L41: = | M41: =PRODUCT(G41,I41,K41) -> 0
C42: 5 | D42: Сухари | G42: 2 | H42: × | I42: =E14 -> 5 | J42: × | K42: =J5 -> 1 | L42: = | M42: =PRODUCT(G42,I42,K42) -> 10 | Q42: =PRODUCT(20,M42) -> 200
C43: 6 | D43: Репчатый лук | G43: 0.25 | H43: × | I43: =E14 -> 5 | J43: × | K43: =J5 -> 1 | L43: = | M43: =PRODUCT(G43,I43,K43) -> 1.25 | Q43: =M43 -> 1.25 | R43: средних
C44: 7 | D44: Лимон в чай
C45: 8 | D45: Взять термос (небольшой)
B46: 4 | C46: Перекус.
B48: 5 | C48: Ужин
C49: 1 | D49: Геркулес | G49: 90 | H49: × | I49: =G8 -> 5 | J49: × | K49: =J5 -> 1 | L49: = | M49: =PRODUCT(G49,I49,K49) -> 450 | Q49: =M49 -> 450
C50: 2 | D50: Пшенка | G50: 80 | H50: × | I50: =I8 -> 0 | J50: × | K50: =J5 -> 1 | L50: = | M50: =PRODUCT(G50,I50,K50) -> 0 | Q50: =M50 -> 0
C51: 3 | D51: Сгущеное молоко | G51: 25 | H51: × | I51: =E8 -> 5 | J51: × | K51: =J5 -> 1 | L51: = | M51: =PRODUCT(G51,I51,K51) -> 125 | Q51: =M51 -> 125
C52: 4 | D52: Макароны(сыр) | G52: 80 | H52: × | I52: =K8 -> 0 | J52: × | K52: =J5 -> 1 | L52: = | M52: =PRODUCT(G52,I52,K52) -> 0 | Q52: =M52 -> 0
C53: 5 | D53: Топленое(сливочное) масло | G53: 25 | H53: × | I53: =E8 -> 5 | J53: × | K53: =J5 -> 1 | L53: = | M53: =PRODUCT(G53,I53,K53) -> 125 | Q53: =M53 -> 125
C54: 6 | D54: Изюм по 1 ст. ложке | G54: 25 | H54: × | I54: =E8 -> 5 | J54: × | K54: =J5 -> 1 | L54: = | M54: =PRODUCT(G54,I54,K54) -> 125 | Q54: =M54 -> 125
...
